Workbook

Sheet Coffe_sales
A1: hour_of_day | B1: cash_type | C1: money | D1: coffee_name | E1: Time_of_Day | F1: Weekday | G1: Month_name | H1: Weekdaysort | I1: Monthsort | J1: Date | K1: Time | M1: IF | N1: IFS | O1: IF +AND | P1: IF+OR | Q1: COUNTIF | R1: COUNTIFS | S1: SUMIF | T1: SUMIFS | U1: AVERAGEIF | V1: AVERAGEIFS | X1: VLOOKUP | Z1: XLOOKUP
A2: 10 | B2: card | C2: 38.7 | D2: Latte | E2: Morning | F2: Fri | G2: Mar | H2: 5 | I2: 3 | J2: 45352 | K2: 0.011001157 | M2: =IF(C2>35,"HIGH","LOW") -> HIGH | N2: {=_xlfn.IFS(C2>35,"HIGH",C2>25,"MIDDLE",TRUE,"LOW")} -> HIGH | O2: =IF(AND(C2>35,E2="MORNING"),"PREMINUM MORNING","OTHERS") -> PREMINUM MORNING | P2: =IF(OR(C2>35,E2="MORNING"),"PREMINUM MORNING","OTHERS") -> PREMINUM MORNING | Q2: =COUNTIF(G:G,"Mar") -> 494 | R2: =COUNTIFS(B:B,"CARD",F:F,"Fri") -> 532 | S2: =SUMIF(G:G,"Mar",C:C) -> 15891.64 | T2: =SUMIFS(C:C,D:D,"LATTE",G:G,"MAR") -> 3392.82 | U2: =AVERAGEIF(G:G,"Mar",C:C) -> 32.169312 | V2: =AVERAGEIFS(C:C,D:D,"LATTE",G:G,"Mar") -> 36.878478 | X2: =VLOOKUP("LATTE",D:E,2,"FALSE") -> Morning | Z2: =_xlfn.XLOOKUP("LATTE",D:D,P:P) -> PREMINUM MORNING
A3: 12 | B3: card | C3: 38.7 | D3: Hot Chocolate | E3: Afternoon | F3: Fri | G3: Mar | H3: 5 | I3: 3 | J3: 45352 | K3: 0.013454861 | M3: =IF(C3>35,"HIGH","LOW") -> HIGH | N3: {=_xlfn.IFS(C3>35,"HIGH",C3>25,"MIDDLE",TRUE,"LOW")} -> HIGH | O3: =IF(AND(C3>35,E3="MORNING"),"PREMINUM MORNING","OTHERS") -> OTHERS | P3: =IF(OR(C3>35,E3="MORNING"),"PREMINUM MORNING","OTHERS") -> PREMINUM MORNING
A4: 12 | B4: card | C4: 38.7 | D4: Hot Chocolate | E4: Afternoon | F4: Fri | G4: Mar | H4: 5 | I4: 3 | J4: 45352 | K4: 0.01409838 | M4: =IF(C4>35,"HIGH","LOW") -> HIGH | N4: {=_xlfn.IFS(C4>35,"HIGH",C4>25,"MIDDLE",TRUE,"LOW")} -> HIGH | O4: =IF(AND(C4>35,E4="MORNING"),"PREMINUM MORNING","OTHERS") -> OTHERS | P4: =IF(OR(C4>35,E4="MORNING"),"PREMINUM MORNING","OTHERS") -> PREMINUM MORNING
A5: 13 | B5: card | C5: 28.9 | D5: Americano | E5: Afternoon | F5: Fri | G5: Mar | H5: 5 | I5: 3 | J5: 45352 | K5: 0.032326389 | M5: =IF(C5>35,"HIGH","LOW") -> LOW | N5: {=_xlfn.IFS(C5>35,"HIGH",C5>25,"MIDDLE",TRUE,"LOW")} -> MIDDLE | O5: =IF(AND(C5>35,E5="MORNING"),"PREMINUM MORNING","OTHERS") -> OTHERS | P5: =IF(OR(C5>35,E5="MORNING"),"PREMINUM MORNING","OTHERS") -> OTHERS
A6: 13 | B6: card | C6: 38.7 | D6: Latte | E6: Afternoon | F6: Fri | G6: Mar | H6: 5 | I6: 3 | J6: 45352 | K6: 0.033502315 | M6: =IF(C6>35,"HIGH","LOW") -> HIGH | N6: {=_xlfn.IFS(C6>35,"HIGH",C6>25,"MIDDLE",TRUE,"LOW")} -> HIGH | O6: =IF(AND(C6>35,E6="MORNING"),"PREMINUM MORNING","OTHERS") -> OTHERS | P6: =IF(OR(C6>35,E6="MORNING"),"PREMINUM MORNING","OTHERS") -> PREMINUM MORNING
A7: 15 | B7: card | C7: 33.8 | D7: Americano with Milk | E7: Afternoon | F7: Fri | G7: Mar | H7: 5 | I7: 3 | J7: 45352 | K7: 0.027635417 | M7: =IF(C7>35,"HIGH","LOW") -> LOW | N7: {=_xlfn.IFS(C7>35,"HIGH",C7>25,"MIDDLE",TRUE,"LOW")} -> MIDDLE | O7: =IF(AND(C7>35,E7="MORNING"),"PREMINUM MORNING","OTHERS") -> OTHERS | P7: =IF(OR(C7>35,E7="MORNING"),"PREMINUM MORNING","OTHERS") -> OTHERS
A8: 16 | B8: card | C8: 38.7 | D8: Hot Chocolate | E8: Afternoon | F8: Fri | G8: Mar | H8: 5 | I8: 3 | J8: 45352 | K8: 0.013226852 | M8: =IF(C8>35,"HIGH","LOW") -> HIGH | N8: {=_xlfn.IFS(C8>35,"HIGH",C8>25,"MIDDLE",TRUE,"LOW")} -> HIGH | O8: =IF(AND(C8>35,E8="MORNING"),"PREMINUM MORNING","OTHERS") -> OTHERS | P8: =IF(OR(C8>35,E8="MORNING"),"PREMINUM MORNING","OTHERS") -> PREMINUM MORNING
A9: 18 | B9: card | C9: 33.8 | D9: Americano with Milk | E9: Night | F9: Fri | G9: Mar | H9: 5 | I9: 3 | J9: 45352 | K9: 0.027125 | M9: =IF(C9>35,"HIGH","LOW") -> LOW | N9: {=_xlfn.IFS(C9>35,"HIGH",C9>25,"MIDDLE",TRUE,"LOW")} -> MIDDLE | O9: =IF(AND(C9>35,E9="MORNING"),"PREMINUM MORNING","OTHERS") -> OTHERS | P9: =IF(OR(C9>35,E9="MORNING"),"PREMINUM MORNING","OTHERS") -> OTHERS
A10: 19 | B10: card | C10: 38.7 | D10: Cocoa | E10: Night | F10: Fri | G10: Mar | H10: 5 | I10: 3 | J10: 45352 | K10: 0.015298611 | M10: =IF(C10>35,"HIGH","LOW") -> HIGH | N10: {=_xlfn.IFS(C10>35,"HIGH",C10>25,"MIDDLE",TRUE,"LOW")} -> HIGH | O10: =IF(AND(C10>35,E10="MORNING"),"PREMINUM MORNING","OTHERS") -> OTHERS | P10: =IF(OR(C10>35,E10="MORNING"),"PREMINUM MORNING","OTHERS") -> PREMINUM MORNING
A11: 19 | B11: card | C11: 33.8 | D11: Americano with Milk | E11: Night | F11: Fri | G11: Mar | H11: 5 | I11: 3 | J11: 45352 | K11: 0.01615625 | M11: =IF(C11>35,"HIGH","LOW") -> LOW | N11: {=_xlfn.IFS(C11>35,"HIGH",C11>25,"MIDDLE",TRUE,"LOW")} -> MIDDLE | O11: =IF(AND(C11>35,E11="MORNING"),"PREMINUM MORNING","OTHERS") -> OTHERS | P11: =IF(OR(C11>35,E11="MORNING"),"PREMINUM MORNING","OTHERS") -> OTHERS
A12: 19 | B12: card | C12: 33.8 | D12: Americano with Milk | E12: Night | F12: Fri | G12: Mar | H12: 5 | I12: 3 | J12: 45352 | K12: 0.020340278 | M12: =IF(C12>35,"HIGH","LOW") -> LOW | N12: {=_xlfn.IFS(C12>35,"HIGH",C12>25,"MIDDLE",TRUE,"LOW")} -> MIDDLE | O12: =IF(AND(C12>35,E12="MORNING"),"PREMINUM MORNING","OTHERS") -> OTHERS | P12: =IF(OR(C12>35,E12="MORNING"),"PREMINUM MORNING","OTHERS") -> OTHERS
A13: 10 | B13: card | C13: 28.9 | D13: Americano | E13: Morning | F13: Sat | G13: Mar | H13: 6 | I13: 3 | J13: 45353 | K13: 0.015358796 | M13: =IF(C13>35,"HIGH","LOW") -> LOW | N13: {=_xlfn.IFS(C13>35,"HIGH",C13>25,"MIDDLE",TRUE,"LOW")} -> MIDDLE | O13: =IF(AND(C13>35,E13="MORNING"),"PREMINUM MORNING","OTHERS") -> OTHERS | P13: =IF(OR(C13>35,E13="MORNING"),"PREMINUM MORNING","OTHERS") -> PREMINUM MORNING
A14: 10 | B14: card | C14: 33.8 | D14: Americano with Milk | E14: Morning | F14: Sat | G14: Mar | H14: 6 | I14: 3 | J14: 45353 | K14: 0.028949074 | M14: =IF(C14>35,"HIGH","LOW") -> LOW | N14: {=_xlfn.IFS(C14>35,"HIGH",C14>25,"MIDDLE",TRUE,"LOW")} -> MIDDLE | O14: =IF(AND(C14>35,E14="MORNING"),"PREMINUM MORNING","OTHERS") -> OTHERS | P14: =IF(OR(C14>35,E14="MORNING"),"PREMINUM MORNING","OTHERS") -> PREMINUM MORNING
... A3548: 18 | B3548: card | C3548: 35.76 | D3548: Latte | E3548: Night | F3548: Sun | G3548: Mar | H3548: 7 | I3548: 3 | J3548: 45739 | K3548: 0.0080856481 | M3548: =IF(C3548>35,"HIGH","LOW") -> HIGH | N3548: {=_xlfn.IFS(C3548>35,"HIGH",C3548>25,"MIDDLE",TRUE,"LOW")} -> HIGH | O3548: =IF(AND(C3548>35,E3548="MORNING"),"PREMINUM MORNING","OTHERS") -> OTHERS | P3548: =IF(OR(C3548>35,E3548="MORNING"),"PREMINUM MORNING","OTHERS") -> PREMINUM MORNING

Sheet Sheet7

Sheet Sheet2
A1: Column1 | B1: Column2
A2: Functions
A3: Sum | B3: =SUM(Coffe_sales!C:C) -> 112245.58
A4: AVG | B4: =AVERAGE(Coffe_sales!C:C) -> 31.645216
A5: MIN | B5: =MIN(Coffe_sales!C:C) -> 18.12
A6: MAX | B6: =MAX(Coffe_sales!C:C) -> 38.7
A7: Count | B7: =COUNT(Coffe_sales!C:C) -> 3547
A8: Counta | B8: =COUNTA(Coffe_sales!C:C) -> 3548
A9: Formulas
A10: IF
A11: IF +AND
A12: IF +OR
A13: IFS
A14: COUNTIF
A15: COUNTIFS
A16: SUMIF
A17: UNIQUE | B17: {=_xlfn.UNIQUE(Coffe_sales!C:C)} -> money
B18: 38.7
B19: 28.9
B20: 33.8
B21: 24
B22: 32.82
B23: 37.72
B24: 27.92
B25: 23.02
B26: 18.12
B27: 35.76
B28: 30.86
B29: 25.96
... B31: 0

Sheet Sheet8
A1: Row Labels | B1: Sum of money
A2: Americano | B2: 14650.26
A3: Americano with Milk | B3: 24751.12
A4: Cappuccino | B4: 17439.14
A5: Cocoa | B5: 8521.16
A6: Cortado | B6: 7384.86
A7: Espresso | B7: 2690.28
A8: Hot Chocolate | B8: 9933.46
A9: Latte | B9: 26875.3
A10: Grand Total | B10: 112245.58
A13: Row Labels | B13: Sum of money
A14: 6 | B14: 149.4
A15: 7 | B15: 2846.02
A16: 8 | B16: 7017.88
A17: 9 | B17: 7264.28
A18: 10 | B18: 10198.52
A19: 11 | B19: 8453.1
A20: 12 | B20: 7419.62
A21: 13 | B21: 7028.76
A22: 14 | B22: 7173.8
A23: 15 | B23: 7476.02
A24: 16 | B24: 9031.84
A25: 17 | B25: 7659.76
... A30: 22 | B30: 3635.16
A31: Grand Total | B31: 112245.58
A33: Row Labels | B33: Sum of money
A34: Afternoon | B34: 38130.04
A35: Morning | B35: 35929.2
A36: Night | B36: 38186.34
A37: Grand Total | B37: 112245.58
A42: Row Labels | B42: Sum of money
A43: Sun | B43: 13336.06
A44: Mon | B44: 17363.1
A45: Tue | B45: 18168.38
A46: Wed | B46: 15750.46
A47: Thu | B47: 16091.4
A48: Fri | B48: 16802.66
A49: Sat | B49: 14733.52
A50: Grand Total | B50: 112245.58
A53: Row Labels | B53: Sum of money
...
